2022-09-25 16:00:41.471618: W tensorflow/stream_executor/platform/default/dso_loader.cc:64] Could not load dynamic library 'libcudart.so.11.0'; dlerror: libcudart.so.11.0: cannot open shared object file: No such file or directory; LD_LIBRARY_PATH: /software/python-anaconda-2021.05-el7-x86_64/lib:/software/cudnn-8.1.0-el7-x86_64+cuda-11.2/lib64
2022-09-25 16:00:41.471846: I tensorflow/stream_executor/cuda/cudart_stub.cc:29] Ignore above cudart dlerror if you do not have a GPU set up on your machine.
2022-09-25 16:01:06.848890: W tensorflow/stream_executor/platform/default/dso_loader.cc:64] Could not load dynamic library 'libcuda.so.1'; dlerror: libcuda.so.1: cannot open shared object file: No such file or directory; LD_LIBRARY_PATH: /software/python-anaconda-2021.05-el7-x86_64/lib:/software/cudnn-8.1.0-el7-x86_64+cuda-11.2/lib64
2022-09-25 16:01:06.849096: W tensorflow/stream_executor/cuda/cuda_driver.cc:269] failed call to cuInit: UNKNOWN ERROR (303)
2022-09-25 16:01:06.849181: I tensorflow/stream_executor/cuda/cuda_diagnostics.cc:156] kernel driver does not appear to be running on this host (midway2-0026.rcc.local): /proc/driver/nvidia/version does not exist
2022-09-25 16:01:06.850329: I tensorflow/core/platform/cpu_feature_guard.cc:193] This TensorFlow binary is optimized with oneAPI Deep Neural Network Library (oneDNN) to use the following CPU instructions in performance-critical operations:  AVX2 FMA
To enable them in other operations, rebuild TensorFlow with the appropriate compiler flags.
Traceback (most recent call last):
  File "standard_variable.py", line 127, in <module>
    logXiH_NN_tf = tf.saved_model.load(outputdir   + 'logXiH_NN')
  File "/home/hqin/.local/lib/python3.8/site-packages/tensorflow/python/saved_model/load.py", line 782, in load
    result = load_partial(export_dir, None, tags, options)["root"]
  File "/home/hqin/.local/lib/python3.8/site-packages/tensorflow/python/saved_model/load.py", line 887, in load_partial
    loader_impl.parse_saved_model_with_debug_info(export_dir))
  File "/home/hqin/.local/lib/python3.8/site-packages/tensorflow/python/saved_model/loader_impl.py", line 57, in parse_saved_model_with_debug_info
    saved_model = parse_saved_model(export_dir)
  File "/home/hqin/.local/lib/python3.8/site-packages/tensorflow/python/saved_model/loader_impl.py", line 115, in parse_saved_model
    raise IOError(
OSError: SavedModel file does not exist at: /project2/lhansen/NN_midway/output/WZVtilde_sigma_K_0040_sigma_Z_0014_sigma_V_0000_sigma_Vtilde_0100/chiUnderline_1000_a_e_0150_a_h_0050_gamma_e_1000_gamma_h_3000_psi_e_1000_psi_h_1000/trial_6_XiE_layers_3_XiH_layers_3_kappa_layers_3_points_size_2_iter_num_15/logXiH_NN/{saved_model.pbtxt|saved_model.pb}
